const addUser = async (req, res) => {
   console.log(req.body)
  try {
    const response = await axios.post(`${env.SPRING_BOOT_API}/api/users`, req.body, {
      headers: { Authorization: req.headers.authorization },
    }
 );
    console.log("problem")
    console.log('Request headers:', { Authorization: req.headers.authorization });
    res.status(response.status).json(response.data);
  } catch (error) {
    console.log('Error forwarding to Spring Boot:', error.response?.status, error.response?.data);
    handleAxiosError(error, res);
  }
}; the data is reaching here, but instead of going to try block it reaches to the catcj block and gives error, why
